Workbook

Sheet Legend
B1: Yo | E1: Big Board Color Grades | F1: NIL + Scholarship Package
E2: P4 Starter | F2: NIL + Scholarship
E3: G5 Starter | F3: NIL + Scholarship
E4: G5 Spot Starter | F4: Scholarship
E5: G5 Backup | F5: Walk On

Sheet Offensive Big Board
A1: =sum(H1,R1,AB1,AL1,AV1,BF1) -> 424 | B1: =SUM(H2,R2,AB2,AL2,AV2,BF2) -> 208 | H1: =count(H3:H1000) -> 43 | R1: =count(R3:R1000) -> 69 | AB1: =count(AB3:AB1000) -> 189 | AL1: =count(AL3:AL1000) -> 36 | AV1: =count(AV3:AV1000) -> 48 | BF1: =count(BF3:BF1000) -> 39
A2: QB | H2: =COUNTIF(J3:J1000, "Y") -> 36 | K2: RB | R2: =COUNTIF(T3:T1000, "Y") -> 23 | U2: WR | AB2: =COUNTIF(AD3:AD1000, "Y") -> 91 | AE2: TE | AL2: =COUNTIF(AN3:AN1000, "Y") -> 21 | AO2: OT | AV2: =COUNTIF(AX3:AX1000, "Y") -> 23 | AY2: IOL | BF2: =COUNTIF(BH3:BH1000, "Y") -> 14
A3: ='QB Formula'!A3&", "&'QB Formula'!B3 -> Brendan Sorsby, Cincinnati | H3: =if('QB Formula'!P3 = 0, " ", 'QB Formula'!P3) -> 5.4921429 | I3: ='QB Formula'!B3 -> Cincinnati | J3: ='QB Formula'!C3 -> Y | K3: ='RB Formula'!A3&", "&'RB Formula'!B3 -> Miles Davis, Utah State | R3: =if('RB Formula'!R3 = 0, " ", 'RB Formula'!S3) -> 5.6583333 | S3: ='RB Formula'!B3 -> Utah State | T3: ='RB Formula'!C3 -> N | U3: ='WR Formula'!A3&", "&'WR Formula'!B3 -> Braden Pegan, Utah State | AB3: =if('WR Formula'!N3 = 0, " ", 'WR Formula'!P3) -> 5.5571429 | AC3: ='WR Formula'!B3 -> Utah State | AD3: ='WR Formula'!C3 -> Y | AE3: ='TE Formula'!A3&", "&'TE Formula'!B3 -> Brody Foley, Tulsa | AL3: =if('TE Formula'!P3 = 0, " ", 'TE Formula'!R3) -> 4.6055556 | AM3: ='TE Formula'!B3 -> Tulsa | AN3: ='TE Formula'!C3 -> Y | AO3: ='OT Formula'!A3&", "&'OT Formula'!B3 -> Spencer Fano, Utah | AV3: =if('OT Formula'!N3 = 0, " ", 'OT Formula'!O3) -> 5.4633333 | AW3: ='OT Formula'!B3 -> Utah | AX3: ='OT Formula'!C3 -> N | AY3: ='IOL Formula'!A3&", "&'IOL Formula'!B3 -> Ryan Berger, Oregon State | BF3: =if('IOL Formula'!N3 = 0, " ", 'IOL Formula'!O3) -> 5.7 | BG3: ='IOL Formula'!B3 -> Oregon State | BH3: ='IOL Formula'!C3 -> N
A4: ='QB Formula'!A4&", "&'QB Formula'!B4 -> Dylan Raiola, Nebraska | H4: =if('QB Formula'!P4 = 0, " ", 'QB Formula'!P4) -> 5.355 | I4: ='QB Formula'!B4 -> Nebraska | J4: ='QB Formula'!C4 -> Y | K4: ='RB Formula'!A4&", "&'RB Formula'!B4 -> Cam Scott, Jacksonville State | R4: =if('RB Formula'!R4 = 0, " ", 'RB Formula'!S4) -> 5.3375 | S4: ='RB Formula'!B4 -> Jacksonville State | T4: ='RB Formula'!C4 -> N | U4: ='WR Formula'!A4&", "&'WR Formula'!B4 -> Jaceon Doss, Towson | AB4: =if('WR Formula'!N4 = 0, " ", 'WR Formula'!P4) -> 5.4 | AC4: ='WR Formula'!B4 -> Towson | AD4: ='WR Formula'!C4 -> N | AE4: ='TE Formula'!A4&", "&'TE Formula'!B4 -> Hayden Hansen, Florida | AL4: =if('TE Formula'!P4 = 0, " ", 'TE Formula'!R4) -> 4.5722222 | AM4: ='TE Formula'!B4 -> Florida | AN4: ='TE Formula'!C4 -> Y | AO4: ='OT Formula'!A4&", "&'OT Formula'!B4 -> Deandre Marshall, UTSA | AV4: =if('OT Formula'!N4 = 0, " ", 'OT Formula'!O4) -> 5.25 | AW4: ='OT Formula'!B4 -> UTSA | AX4: ='OT Formula'!C4 -> N | AY4: ='IOL Formula'!A4&", "&'IOL Formula'!B4 -> Johnny Dickson III, North Texas | BF4: =if('IOL Formula'!N4 = 0, " ", 'IOL Formula'!O4) -> 5.2333333 | BG4: ='IOL Formula'!B4 -> North Texas | BH4: ='IOL Formula'!C4 -> N
A5: ='QB Formula'!A5&", "&'QB Formula'!B5 -> DJ Lagway, Florida | H5: =if('QB Formula'!P5 = 0, " ", 'QB Formula'!P5) -> 5.2671429 | I5: ='QB Formula'!B5 -> Florida | J5: ='QB Formula'!C5 -> Y | K5: ='RB Formula'!A5&", "&'RB Formula'!B5 -> Xai'Shaun Edwards, Houston Christian | R5: =if('RB Formula'!R5 = 0, " ", 'RB Formula'!S5) -> 5.3375 | S5: ='RB Formula'!B5 -> Houston Christian | T5: ='RB Formula'!C5 -> Y | U5: ='WR Formula'!A5&", "&'WR Formula'!B5 -> Tyran Warren, Alcorn State | AB5: =if('WR Formula'!N5 = 0, " ", 'WR Formula'!P5) -> 5.3428571 | AC5: ='WR Formula'!B5 -> Alcorn State | AD5: ='WR Formula'!C5 -> N | AE5: ='TE Formula'!A5&", "&'TE Formula'!B5 -> Dallen Bentley, Utah | AL5: =if('TE Formula'!P5 = 0, " ", 'TE Formula'!R5) -> 4.5444444 | AM5: ='TE Formula'!B5 -> Utah | AN5: ='TE Formula'!C5 -> N | AO5: ='OT Formula'!A5&", "&'OT Formula'!B5 -> Caleb Lomu, Utah | AV5: =if('OT Formula'!N5 = 0, " ", 'OT Formula'!O5) -> 5.21 | AW5: ='OT Formula'!B5 -> Utah | AX5: ='OT Formula'!C5 -> N | AY5: ='IOL Formula'!A5&", "&'IOL Formula'!B5 -> Joep Engbers, Liberty | BF5: =if('IOL Formula'!N5 = 0, " ", 'IOL Formula'!O5) -> 5.2333333 | BG5: ='IOL Formula'!B5 -> Liberty | BH5: ='IOL Formula'!C5 -> N
A6: ='QB Formula'!A6&", "&'QB Formula'!B6 -> Drew Mestemaker, North Texas | H6: =if('QB Formula'!P6 = 0, " ", 'QB Formula'!P6) -> 5.2357143 | I6: ='QB Formula'!B6 -> North Texas | J6: ='QB Formula'!C6 -> Y | K6: ='RB Formula'!A6&", "&'RB Formula'!B6 -> Nykahi Davenport, USF | R6: =if('RB Formula'!R6 = 0, " ", 'RB Formula'!S6) -> 5.3375 | S6: ='RB Formula'!B6 -> USF | T6: ='RB Formula'!C6 -> N | U6: ='WR Formula'!A6&", "&'WR Formula'!B6 -> Jordan Garrison, Cal Poly | AB6: =if('WR Formula'!N6 = 0, " ", 'WR Formula'!P6) -> 5.2428571 | AC6: ='WR Formula'!B6 -> Cal Poly | AD6: ='WR Formula'!C6 -> N | AE6: ='TE Formula'!A6&", "&'TE Formula'!B6 -> Jett Carpenter, Nevada | AL6: =if('TE Formula'!P6 = 0, " ", 'TE Formula'!R6) -> 4.5055556 | AM6: ='TE Formula'!B6 -> Nevada | AN6: ='TE Formula'!C6 -> Y | AO6: ='OT Formula'!A6&", "&'OT Formula'!B6 -> Brayden Walton, Fresno State | AV6: =if('OT Formula'!N6 = 0, " ", 'OT Formula'!O6) -> 5.0433333 | AW6: ='OT Formula'!B6 -> Fresno State | AX6: ='OT Formula'!C6 -> N | AY6: ='IOL Formula'!A6&", "&'IOL Formula'!B6 -> Malachi Breland, Memphis | BF6: =if('IOL Formula'!N6 = 0, " ", 'IOL Formula'!O6) -> 5.1866667 | BG6: ='IOL Formula'!B6 -> Memphis | BH6: ='IOL Formula'!C6 -> N
A7: ='QB Formula'!A7&", "&'QB Formula'!B7 -> Jaden Craig, Harvard | H7: =if('QB Formula'!P7 = 0, " ", 'QB Formula'!P7) -> 5.1892857 | I7: ='QB Formula'!B7 -> Harvard | J7: ='QB Formula'!C7 -> Y | K7: ='RB Formula'!A7&", "&'RB Formula'!B7 -> Jimmyll Williams, Elon | R7: =if('RB Formula'!R7 = 0, " ", 'RB Formula'!S7) -> 5.3375 | S7: ='RB Formula'!B7 -> Elon | T7: ='RB Formula'!C7 -> Y | U7: ='WR Formula'!A7&", "&'WR Formula'!B7 -> Aidan Mizell, Florida | AB7: =if('WR Formula'!N7 = 0, " ", 'WR Formula'!P7) -> 5.2 | AC7: ='WR Formula'!B7 -> Florida | AD7: ='WR Formula'!C7 -> Y | AE7: ='TE Formula'!A7&", "&'TE Formula'!B7 -> Lacota Dippre, James Madison | AL7: =if('TE Formula'!P7 = 0, " ", 'TE Formula'!R7) -> 4.4222222 | AM7: ='TE Formula'!B7 -> James Madison | AN7: ='TE Formula'!C7 -> N | AO7: ='OT Formula'!A7&", "&'OT Formula'!B7 -> Grant Seagren, Oklahoma State | AV7: =if('OT Formula'!N7 = 0, " ", 'OT Formula'!O7) -> 5.0433333 | AW7: ='OT Formula'!B7 -> Oklahoma State | AX7: ='OT Formula'!C7 -> Y | AY7: ='IOL Formula'!A7&", "&'IOL Formula'!B7 -> Wes King, Wyoming | BF7: =if('IOL Formula'!N7 = 0, " ", 'IOL Formula'!O7) -> 5.1866667 | BG7: ='IOL Formula'!B7 -> Wyoming | BH7: ='IOL Formula'!C7 -> N
A8: ='QB Formula'!A8&", "&'QB Formula'!B8 -> Hauss Hejny, Oklahoma State | H8: =if('QB Formula'!P8 = 0, " ", 'QB Formula'!P8) -> 4.9971429 | I8: ='QB Formula'!B8 -> Oklahoma State | J8: ='QB Formula'!C8 -> N | K8: ='RB Formula'!A8&", "&'RB Formula'!B8 -> Dason Brooks, Idaho State | R8: =if('RB Formula'!R8 = 0, " ", 'RB Formula'!S8) -> 5.2791667 | S8: ='RB Formula'!B8 -> Idaho State | T8: ='RB Formula'!C8 -> N | U8: ='WR Formula'!A8&", "&'WR Formula'!B8 -> Donte Lee Jr., Liberty | AB8: =if('WR Formula'!N8 = 0, " ", 'WR Formula'!P8) -> 5.1857143 | AC8: ='WR Formula'!B8 -> Liberty | AD8: ='WR Formula'!C8 -> Y | AE8: ='TE Formula'!A8&", "&'TE Formula'!B8 -> Darrin Fugitt, Lindenwood | AL8: =if('TE Formula'!P8 = 0, " ", 'TE Formula'!R8) -> 4.4222222 | AM8: ='TE Formula'!B8 -> Lindenwood | AN8: ='TE Formula'!C8 -> Y | AO8: ='OT Formula'!A8&", "&'OT Formula'!B8 -> Miles McVay, North Carolina | AV8: =if('OT Formula'!N8 = 0, " ", 'OT Formula'!O8) -> 4.9966667 | AW8: ='OT Formula'!B8 -> North Carolina | AX8: ='OT Formula'!C8 -> Y | AY8: ='IOL Formula'!A8&", "&'IOL Formula'!B8 -> Aaron Fenimore, Liberty | BF8: =if('IOL Formula'!N8 = 0, " ", 'IOL Formula'!O8) -> 5.0233333 | BG8: ='IOL Formula'!B8 -> Liberty | BH8: ='IOL Formula'!C8 -> N
A9: ='QB Formula'!A9&", "&'QB Formula'!B9 -> Josh Hoover, TCU | H9: =if('QB Formula'!P9 = 0, " ", 'QB Formula'!P9) -> 4.9921429 | I9: ='QB Formula'!B9 -> TCU | J9: ='QB Formula'!C9 -> Y | K9: ='RB Formula'!A9&", "&'RB Formula'!B9 -> Landen Chambers, Cental Arkansas | R9: =if('RB Formula'!R9 = 0, " ", 'RB Formula'!S9) -> 5.2791667 | S9: ='RB Formula'!B9 -> Cental Arkansas | T9: ='RB Formula'!C9 -> Y | U9: ='WR Formula'!A9&", "&'WR Formula'!B9 -> AJ Wilson, UTSA | AB9: =if('WR Formula'!N9 = 0, " ", 'WR Formula'!P9) -> 5.1857143 | AC9: ='WR Formula'!B9 -> UTSA | AD9: ='WR Formula'!C9 -> N | AE9: ='TE Formula'!A9&", "&'TE Formula'!B9 -> Randy Pittman Jr, Florida State | AL9: =if('TE Formula'!P9 = 0, " ", 'TE Formula'!R9) -> 4.4222222 | AM9: ='TE Formula'!B9 -> Florida State | AN9: ='TE Formula'!C9 -> Y | AO9: ='OT Formula'!A9&", "&'OT Formula'!B9 -> Nate Hale, San Jose State | AV9: =if('OT Formula'!N9 = 0, " ", 'OT Formula'!O9) -> 4.8333333 | AW9: ='OT Formula'!B9 -> San Jose State | AX9: ='OT Formula'!C9 -> Y | AY9: ='IOL Formula'!A9&", "&'IOL Formula'!B9 -> Xavier Allen, Bucknell | BF9: =if('IOL Formula'!N9 = 0, " ", 'IOL Formula'!O9) -> 5.0233333 | BG9: ='IOL Formula'!B9 -> Bucknell | BH9: ='IOL Formula'!C9 -> Y
A10: ='QB Formula'!A10&", "&'QB Formula'!B10 -> Jax Leatherwood, SEMO | H10: =if('QB Formula'!P10 = 0, " ", 'QB Formula'!P10) -> 4.7957143 | I10: ='QB Formula'!B10 -> SEMO | J10: ='QB Formula'!C10 -> Y | K10: ='RB Formula'!A10&", "&'RB Formula'!B10 -> Nick Osho, Indiana State | R10: =if('RB Formula'!R10 = 0, " ", 'RB Formula'!S10) -> 5.2791667 | S10: ='RB Formula'!B10 -> Indiana State | T10: ='RB Formula'!C10 -> Y | U10: ='WR Formula'!A10&", "&'WR Formula'!B10 -> Jalen Jones, Alabama State | AB10: =if('WR Formula'!N10 = 0, " ", 'WR Formula'!P10) -> 5.1857143 | AC10: ='WR Formula'!B10 -> Alabama State | AD10: ='WR Formula'!C10 -> N | AE10: ='TE Formula'!A10&", "&'TE Formula'!B10 -> Ismael Smith Flores, UTRGV | AL10: =if('TE Formula'!P10 = 0, " ", 'TE Formula'!R10) -> 4.3 | AM10: ='TE Formula'!B10 -> UTRGV | AN10: ='TE Formula'!C10 -> Y | AO10: ='OT Formula'!A10&", "&'OT Formula'!B10 -> Henry Tabansi, Buffalo | AV10: =if('OT Formula'!N10 = 0, " ", 'OT Formula'!O10) -> 4.7866667 | AW10: ='OT Formula'!B10 -> Buffalo | AX10: ='OT Formula'!C10 -> N | AY10: ='IOL Formula'!A10&", "&'IOL Formula'!B10 -> Nathan Elu, Oregon State | BF10: =if('IOL Formula'!N10 = 0, " ", 'IOL Formula'!O10) -> 4.9766667 | BG10: ='IOL Formula'!B10 -> Oregon State | BH10: ='IOL Formula'!C10 -> N
A11: ='QB Formula'!A11&", "&'QB Formula'!B11 -> Colton Joseph, Old Dominion | H11: =if('QB Formula'!P11 = 0, " ", 'QB Formula'!P11) -> 4.7771429 | I11: ='QB Formula'!B11 -> Old Dominion | J11: ='QB Formula'!C11 -> Y | K11: ='RB Formula'!A11&", "&'RB Formula'!B11 -> Carson Groseck, Gardner-Webb | R11: =if('RB Formula'!R11 = 0, " ", 'RB Formula'!S11) -> 5.0166667 | S11: ='RB Formula'!B11 -> Gardner-Webb | T11: ='RB Formula'!C11 -> Y | U11: ='WR Formula'!A11&", "&'WR Formula'!B11 -> Nick Marsh, Michigan State | AB11: =if('WR Formula'!N11 = 0, " ", 'WR Formula'!P11) -> 5.1857143 | AC11: ='WR Formula'!B11 -> Michigan State | AD11: ='WR Formula'!C11 -> Y | AE11: ='TE Formula'!A11&", "&'TE Formula'!B11 -> Kristian Ingman, Portland State | AL11: =if('TE Formula'!P11 = 0, " ", 'TE Formula'!R11) -> 4.2833333 | AM11: ='TE Formula'!B11 -> Portland State | AN11: ='TE Formula'!C11 -> N | AO11: ='OT Formula'!A11&", "&'OT Formula'!B11 -> Rex Johnsen, Wyoming | AV11: =if('OT Formula'!N11 = 0, " ", 'OT Formula'!O11) -> 4.7866667 | AW11: ='OT Formula'!B11 -> Wyoming | AX11: ='OT Formula'!C11 -> N | AY11: ='IOL Formula'!A11&", "&'IOL Formula'!B11 -> Michael Mokofisi, Utah | BF11: =if('IOL Formula'!N11 = 0, " ", 'IOL Formula'!O11) -> 4.97 | BG11: ='IOL Formula'!B11 -> Utah | BH11: ='IOL Formula'!C11 -> N
A12: ='QB Formula'!A12&", "&'QB Formula'!B12 -> Devon Dampier, Utah | H12: =if('QB Formula'!P12 = 0, " ", 'QB Formula'!P12) -> 4.5742857 | I12: ='QB Formula'!B12 -> Utah | J12: ='QB Formula'!C12 -> N | K12: ='RB Formula'!A12&", "&'RB Formula'!B12 -> Justin Montgomery, Presbyterian | R12: =if('RB Formula'!R12 = 0, " ", 'RB Formula'!S12) -> 5.0166667 | S12: ='RB Formula'!B12 -> Presbyterian | T12: ='RB Formula'!C12 -> Y | U12: ='WR Formula'!A12&", "&'WR Formula'!B12 -> Larenzo Fenner, South Dakota | AB12: =if('WR Formula'!N12 = 0, " ", 'WR Formula'!P12) -> 5.1142857 | AC12: ='WR Formula'!B12 -> South Dakota | AD12: ='WR Formula'!C12 -> N | AE12: ='TE Formula'!A12&", "&'TE Formula'!B12 -> Jayvontay Conner, East Carolina | AL12: =if('TE Formula'!P12 = 0, " ", 'TE Formula'!R12) -> 4.2277778 | AM12: ='TE Formula'!B12 -> East Carolina | AN12: ='TE Formula'!C12 -> Y | AO12: ='OT Formula'!A12&", "&'OT Formula'!B12 -> Ethan Green, Cincinnati | AV12: =if('OT Formula'!N12 = 0, " ", 'OT Formula'!O12) -> 4.7866667 | AW12: ='OT Formula'!B12 -> Cincinnati | AX12: ='OT Formula'!C12 -> Y | AY12: ='IOL Formula'!A12&", "&'IOL Formula'!B12 -> Dylan Sikorski, Oregon State | BF12: =if('IOL Formula'!N12 = 0, " ", 'IOL Formula'!O12) -> 4.8133333 | BG12: ='IOL Formula'!B12 -> Oregon State | BH12: ='IOL Formula'!C12 -> Y
A13: ='QB Formula'!A13&", "&'QB Formula'!B13 -> Byrd Ficklin, Utah | H13: =if('QB Formula'!P13 = 0, " ", 'QB Formula'!P13) -> 4.5392857 | I13: ='QB Formula'!B13 -> Utah | J13: ='QB Formula'!C13 -> N | K13: ='RB Formula'!A13&", "&'RB Formula'!B13 -> Ofa Mataele, Western Michigan | R13: =if('RB Formula'!R13 = 0, " ", 'RB Formula'!S13) -> 4.9583333 | S13: ='RB Formula'!B13 -> Western Michigan | T13: ='RB Formula'!C13 -> N | U13: ='WR Formula'!A13&", "&'WR Formula'!B13 -> Jayshon Platt, FAU | AB13: =if('WR Formula'!N13 = 0, " ", 'WR Formula'!P13) -> 5.0428571 | AC13: ='WR Formula'!B13 -> FAU | AD13: ='WR Formula'!C13 -> Y | AE13: ='TE Formula'!A13&", "&'TE Formula'!B13 -> Mason Williams, Ohio | AL13: =if('TE Formula'!P13 = 0, " ", 'TE Formula'!R13) -> 4.2277778 | AM13: ='TE Formula'!B13 -> Ohio | AN13: ='TE Formula'!C13 -> N | AO13: ='OT Formula'!A13&", "&'OT Formula'!B13 -> Reese Baker, Tulane | AV13: =if('OT Formula'!N13 = 0, " ", 'OT Formula'!O13) -> 4.7433333 | AW13: ='OT Formula'!B13 -> Tulane | AX13: ='OT Formula'!C13 -> N | AY13: ='IOL Formula'!A13&", "&'IOL Formula'!B13 -> Cayden Sweatt, App State | BF13: =if('IOL Formula'!N13 = 0, " ", 'IOL Formula'!O13) -> 4.7033333 | BG13: ='IOL Formula'!B13 -> App State | BH13: ='IOL Formula'!C13 -> N
A14: ='QB Formula'!A14&", "&'QB Formula'!B14 -> Grant Jordan, UMass | H14: =if('QB Formula'!P14 = 0, " ", 'QB Formula'!P14) -> 4.5021429 | I14: ='QB Formula'!B14 -> UMass | J14: ='QB Formula'!C14 -> Y | K14: ='RB Formula'!A14&", "&'RB Formula'!B14 -> LJ Phillips, South Dakota | R14: =if('RB Formula'!R14 = 0, " ", 'RB Formula'!S14) -> 4.9583333 | S14: ='RB Formula'!B14 -> South Dakota | T14: ='RB Formula'!C14 -> Y | U14: ='WR Formula'!A14&", "&'WR Formula'!B14 -> Ernest Campbell, Sacramento State | AB14: =if('WR Formula'!N14 = 0, " ", 'WR Formula'!P14) -> 5.0285714 | AC14: ='WR Formula'!B14 -> Sacramento State | AD14: ='WR Formula'!C14 -> Y | AE14: ='TE Formula'!A14&", "&'TE Formula'!B14 -> Levi Linowes, Brown | AL14: =if('TE Formula'!P14 = 0, " ", 'TE Formula'!R14) -> 4.0611111 | AM14: ='TE Formula'!B14 -> Brown | AN14: ='TE Formula'!C14 -> N | AO14: ='OT Formula'!A14&", "&'OT Formula'!B14 -> Netinho Olivieri, Penn | AV14: =if('OT Formula'!N14 = 0, " ", 'OT Formula'!O14) -> 4.7433333 | AW14: ='OT Formula'!B14 -> Penn | AX14: ='OT Formula'!C14 -> Y | AY14: ='IOL Formula'!A14&", "&'IOL Formula'!B14 -> Shalik Hubbard, Monmouth | BF14: =if('IOL Formula'!N14 = 0, " ", 'IOL Formula'!O14) -> 4.7033333 | BG14: ='IOL Formula'!B14 -> Monmouth | BH14: ='IOL Formula'!C14 -> Y
... A31: ='QB Formula'!A31&", "&'QB Formula'!B31 -> Amari Odom, Kennesaw State | H31: =if('QB Formula'!P31 = 0, " ", 'QB Formula'!P31) -> 4.04309 | I31: ='QB Formula'!B31 -> Kennesaw State | J31: ='QB Formula'!C31 -> N | K31: ='RB Formula'!A31&", "&'RB Formula'!B31 -> Clay Thevenin, Louisiana Tech | R31: =if('RB Formula'!R31 = 0, " ", 'RB Formula'!S31) -> 4.375 | S31: ='RB Formula'!B31 -> Louisiana Tech | T31: ='RB Formula'!C31 -> N | U31: ='WR Formula'!A31&", "&'WR Formula'!B31 -> Yannick Smith, ECU | AB31: =if('WR Formula'!N31 = 0, " ", 'WR Formula'!P31) -> 4.7571429 | AC31: ='WR Formula'!B31 -> ECU | AD31: ='WR Formula'!C31 -> Y | AE31: ='TE Formula'!A31&", "&'TE Formula'!B31 -> Fisher Clements, Northern Colorado | AL31: =if('TE Formula'!P31 = 0, " ", 'TE Formula'!R31) -> 3.5888889 | AM31: ='TE Formula'!B31 -> Northern Colorado | AN31: ='TE Formula'!C31 -> Y | AO31: ='OT Formula'!A31&", "&'OT Formula'!B31 -> Everett Small, Eastern Michigan | AV31: =if('OT Formula'!N31 = 0, " ", 'OT Formula'!O31) -> 4.2766667 | AW31: ='OT Formula'!B31 -> Eastern Michigan | AX31: ='OT Formula'!C31 -> N | AY31: ='IOL Formula'!A31&", "&'IOL Formula'!B31 -> Malachi Preciado, South Alabama | BF31: =if('IOL Formula'!N31 = 0, " ", 'IOL Formula'!O31) -> 3.98 | BG31: ='IOL Formula'!B31 -> South Alabama | BH31: ='IOL Formula'!C31 -> Y
A32: ='QB Formula'!A32&", "&'QB Formula'!B32 -> Coulter Cleland, Davidson | H32: =if('QB Formula'!P32 = 0, " ", 'QB Formula'!P32) -> 4.0171429 | J32: ='QB Formula'!C32 -> Y | K32: ='RB Formula'!A32&", "&'RB Formula'!B32 -> Terron Kellman, Wyoming | R32: =if('RB Formula'!R32 = 0, " ", 'RB Formula'!S32) -> 4.375 | S32: ='RB Formula'!B32 -> Wyoming | T32: ='RB Formula'!C32 -> Y | U32: ='WR Formula'!A32&", "&'WR Formula'!B32 -> Omarion Miller, Colorado | AB32: =if('WR Formula'!N32 = 0, " ", 'WR Formula'!P32) -> 4.7571429 | AC32: ='WR Formula'!B32 -> Colorado | AD32: ='WR Formula'!C32 -> Y | AE32: ='TE Formula'!A32&", "&'TE Formula'!B32 -> Marcus Middleton, Monmouth | AL32: =if('TE Formula'!P32 = 0, " ", 'TE Formula'!R32) -> 3.55 | AM32: ='TE Formula'!B32 -> Monmouth | AN32: ='TE Formula'!C32 -> N | AO32: ='OT Formula'!A32&", "&'OT Formula'!B32 -> Ashton Tripp, Washington State | AV32: =if('OT Formula'!N32 = 0, " ", 'OT Formula'!O32) -> 4.2766667 | AW32: ='OT Formula'!B32 -> Washington State | AX32: ='OT Formula'!C32 -> N | AY32: ='IOL Formula'!A32&", "&'IOL Formula'!B32 -> Steven Demboski, Delaware | BF32: =if('IOL Formula'!N32 = 0, " ", 'IOL Formula'!O32) -> 3.9333333 | BG32: ='IOL Formula'!B32 -> Delaware | BH32: ='IOL Formula'!C32 -> N
A33: ='QB Formula'!A33&", "&'QB Formula'!B33 -> Nick Josifek, Idaho | H33: =if('QB Formula'!P33 = 0, " ", 'QB Formula'!P33) -> 3.8771429 | J33: ='QB Formula'!C33 -> Y | K33: ='RB Formula'!A33&", "&'RB Formula'!B33 -> Wayne Knight, James Madison | R33: =if('RB Formula'!R33 = 0, " ", 'RB Formula'!S33) -> 4.375 | S33: ='RB Formula'!B33 -> James Madison | T33: ='RB Formula'!C33 -> N | U33: ='WR Formula'!A33&", "&'WR Formula'!B33 -> Tony Freeman, Washington State | AB33: =if('WR Formula'!N33 = 0, " ", 'WR Formula'!P33) -> 4.7428571 | AC33: ='WR Formula'!B33 -> Washington State | AD33: ='WR Formula'!C33 -> Y | AE33: ='TE Formula'!A33&", "&'TE Formula'!B33 -> Eli Finley, Louisiana Tech | AL33: =if('TE Formula'!P33 = 0, " ", 'TE Formula'!R33) -> 3.3111111 | AM33: ='TE Formula'!B33 -> Louisiana Tech | AN33: ='TE Formula'!C33 -> N | AO33: ='OT Formula'!A33&", "&'OT Formula'!B33 -> Johnnie Brown III, Georgia Southern | AV33: =if('OT Formula'!N33 = 0, " ", 'OT Formula'!O33) -> 4.2766667 | AW33: ='OT Formula'!B33 -> Georgia Southern | AX33: ='OT Formula'!C33 -> N | AY33: ='IOL Formula'!A33&", "&'IOL Formula'!B33 -> Joseph Harbert, San Jose State | BF33: =if('IOL Formula'!N33 = 0, " ", 'IOL Formula'!O33) -> 3.7233333 | BG33: ='IOL Formula'!B33 -> San Jose State | BH33: ='IOL Formula'!C33 -> N
A34: ='QB Formula'!A34&", "&'QB Formula'!B34 -> Harrison Burch, Kentucky Wesleyan | H34: =if('QB Formula'!P34 = 0, " ", 'QB Formula'!P34) -> 3.8771429 | J34: ='QB Formula'!C34 -> Y | K34: ='RB Formula'!A34&", "&'RB Formula'!B34 -> Lucky Sutton, San Diego State | R34: =if('RB Formula'!R34 = 0, " ", 'RB Formula'!S34) -> 4.375 | S34: ='RB Formula'!B34 -> San Diego State | T34: ='RB Formula'!C34 -> N | U34: ='WR Formula'!A34&", "&'WR Formula'!B34 -> Jared Richardson, UPenn | AB34: =if('WR Formula'!N34 = 0, " ", 'WR Formula'!P34) -> 4.6857143 | AC34: ='WR Formula'!B34 -> UPenn | AD34: ='WR Formula'!C34 -> Y | AE34: ='TE Formula'!A34&", "&'TE Formula'!B34 -> Hyatt Timosciek, Tenessee Martin | AL34: =if('TE Formula'!P34 = 0, " ", 'TE Formula'!R34) -> 3.3111111 | AM34: ='TE Formula'!B34 -> Tenessee Martin | AN34: ='TE Formula'!C34 -> Y | AO34: ='OT Formula'!A34&", "&'OT Formula'!B34 -> Riley McGehee, Arkansas State | AV34: =if('OT Formula'!N34 = 0, " ", 'OT Formula'!O34) -> 4.2766667 | AW34: ='OT Formula'!B34 -> Arkansas State | AX34: ='OT Formula'!C34 -> N | AY34: ='IOL Formula'!A34&", "&'IOL Formula'!B34 -> Jack Leyrer, Stanford | BF34: =if('IOL Formula'!N34 = 0, " ", 'IOL Formula'!O34) -> 3.7233333 | BG34: ='IOL Formula'!B34 -> Stanford | BH34: ='IOL Formula'!C34 -> Y
A35: ='QB Formula'!A35&", "&'QB Formula'!B35 -> Nicco Marchiol, West Virginia | H35: =if('QB Formula'!P35 = 0, " ", 'QB Formula'!P35) -> 3.8771429 | J35: ='QB Formula'!C35 -> Y | K35: ='RB Formula'!A35&", "&'RB Formula'!B35 -> Nick Herman, Drake | R35: =if('RB Formula'!R35 = 0, " ", 'RB Formula'!S35) -> 4.375 | S35: ='RB Formula'!B35 -> Drake | T35: ='RB Formula'!C35 -> N | U35: ='WR Formula'!A35&", "&'WR Formula'!B35 -> Kyan Mason, Akron | AB35: =if('WR Formula'!N35 = 0, " ", 'WR Formula'!P35) -> 4.6714286 | AC35: ='WR Formula'!B35 -> Akron | AD35: ='WR Formula'!C35 -> N | AE35: ='TE Formula'!A35&", "&'TE Formula'!B35 -> Dylan Magazu, Elon | AL35: =if('TE Formula'!P35 = 0, " ", 'TE Formula'!R35) -> 3.2555556 | AM35: ='TE Formula'!B35 -> Elon | AN35: ='TE Formula'!C35 -> N | AO35: ='OT Formula'!A35&", "&'OT Formula'!B35 -> Eric Smith, Miami OH | AV35: =if('OT Formula'!N35 = 0, " ", 'OT Formula'!O35) -> 4.0666667 | AW35: ='OT Formula'!B35 -> Miami OH | AX35: ='OT Formula'!C35 -> N | AY35: ='IOL Formula'!A35&", "&'IOL Formula'!B35 -> Carter Sweazie, James Madison | BF35: =if('IOL Formula'!N35 = 0, " ", 'IOL Formula'!O35) -> 3.6066667 | BG35: ='IOL Formula'!B35 -> James Madison | BH35: ='IOL Formula'!C35 -> N
A36: ='QB Formula'!A36&", "&'QB Formula'!B36 -> Davin Wydner, West Georgia | H36: =if('QB Formula'!P36 = 0, " ", 'QB Formula'!P36) -> 3.7959471 | J36: ='QB Formula'!C36 -> Y | K36: ='RB Formula'!A36&", "&'RB Formula'!B36 -> Sutton Smith, Memphis | R36: =if('RB Formula'!R36 = 0, " ", 'RB Formula'!S36) -> 4.375 | S36: ='RB Formula'!B36 -> Memphis | T36: ='RB Formula'!C36 -> N | U36: ='WR Formula'!A36&", "&'WR Formula'!B36 -> Kyri Shoals, San Jose State | AB36: =if('WR Formula'!N36 = 0, " ", 'WR Formula'!P36) -> 4.6285714 | AC36: ='WR Formula'!B36 -> San Jose State | AD36: ='WR Formula'!C36 -> Y | AE36: ='TE Formula'!A36&", "&'TE Formula'!B36 -> Ryder Kurtz, Cornell | AL36: =if('TE Formula'!P36 = 0, " ", 'TE Formula'!R36) -> 3.1611111 | AM36: ='TE Formula'!B36 -> Cornell | AN36: ='TE Formula'!C36 -> N | AO36: ='OT Formula'!A36&", "&'OT Formula'!B36 -> Hayes Creel, Southern Miss | AV36: =if('OT Formula'!N36 = 0, " ", 'OT Formula'!O36) -> 4.0666667 | AW36: ='OT Formula'!B36 -> Southern Miss | AX36: ='OT Formula'!C36 -> N | AY36: ='IOL Formula'!A36&", "&'IOL Formula'!B36 -> Nate Bledsoe, Rice | BF36: =if('IOL Formula'!N36 = 0, " ", 'IOL Formula'!O36) -> 3.5966667 | BG36: ='IOL Formula'!B36 -> Rice | BH36: ='IOL Formula'!C36 -> N
A37: ='QB Formula'!A37&", "&'QB Formula'!B37 -> Drew Devillier, Rice | H37: =if('QB Formula'!P37 = 0, " ", 'QB Formula'!P37) -> 3.7809471 | J37: ='QB Formula'!C37 -> Y | K37: ='RB Formula'!A37&", "&'RB Formula'!B37 -> Joshua Dye, Southern Utah | R37: =if('RB Formula'!R37 = 0, " ", 'RB Formula'!S37) -> 4.375 | S37: ='RB Formula'!B37 -> Southern Utah | T37: ='RB Formula'!C37 -> Y | U37: ='WR Formula'!A37&", "&'WR Formula'!B37 -> Nik McMillan, Buffalo | AB37: =if('WR Formula'!N37 = 0, " ", 'WR Formula'!P37) -> 4.6 | AC37: ='WR Formula'!B37 -> Buffalo | AD37: ='WR Formula'!C37 -> Y | AE37: ='TE Formula'!A37&", "&'TE Formula'!B37 -> Sean McElwain, William and Mary | AL37: =if('TE Formula'!P37 = 0, " ", 'TE Formula'!R37) -> 2.9833333 | AM37: ='TE Formula'!B37 -> William and Mary | AN37: ='TE Formula'!C37 -> N | AO37: ='OT Formula'!A37&", "&'OT Formula'!B37 -> Daughtry Richardson, FAU | AV37: =if('OT Formula'!N37 = 0, " ", 'OT Formula'!O37) -> 4.0666667 | AW37: ='OT Formula'!B37 -> FAU | AX37: ='OT Formula'!C37 -> Y | AY37: ='IOL Formula'!A37&", "&'IOL Formula'!B37 -> Tristian Smith, Arkansas State | BF37: =if('IOL Formula'!N37 = 0, " ", 'IOL Formula'!O37) -> 3.3933333 | BG37: ='IOL Formula'!B37 -> Arkansas State | BH37: ='IOL Formula'!C37 -> N
A38: ='QB Formula'!A38&", "&'QB Formula'!B38 -> Brandon Tennison, UTSA | H38: =if('QB Formula'!P38 = 0, " ", 'QB Formula'!P38) -> 3.7009471 | J38: ='QB Formula'!C38 -> N | K38: ='RB Formula'!A38&", "&'RB Formula'!B38 -> Carter Vargas, UC Davis | R38: =if('RB Formula'!R38 = 0, " ", 'RB Formula'!S38) -> 4.375 | S38: ='RB Formula'!B38 -> UC Davis | T38: ='RB Formula'!C38 -> Y | U38: ='WR Formula'!A38&", "&'WR Formula'!B38 -> Omari Hayes, Tulane | AB38: =if('WR Formula'!N38 = 0, " ", 'WR Formula'!P38) -> 4.6 | AC38: ='WR Formula'!B38 -> Tulane | AD38: ='WR Formula'!C38 -> N | AE38: ='TE Formula'!A38&", "&'TE Formula'!B38 -> Gavin Harris, New Mexico State | AL38: =if('TE Formula'!P38 = 0, " ", 'TE Formula'!R38) -> 2.8111111 | AM38: ='TE Formula'!B38 -> New Mexico State | AN38: ='TE Formula'!C38 -> Y | AO38: ='OT Formula'!A38&", "&'OT Formula'!B38 -> Evan Malcore, NIU | AV38: =if('OT Formula'!N38 = 0, " ", 'OT Formula'!O38) -> 4.0633333 | AW38: ='OT Formula'!B38 -> NIU | AX38: ='OT Formula'!C38 -> Y | AY38: ='IOL Formula'!A38&", "&'IOL Formula'!B38 -> Kadin Lynch, William & Mary | BF38: =if('IOL Formula'!N38 = 0, " ", 'IOL Formula'!O38) -> 3.3033333 | BG38: ='IOL Formula'!B38 -> William & Mary | BH38: ='IOL Formula'!C38 -> Y
A39: ='QB Formula'!A39&", "&'QB Formula'!B39 -> Liam O'Brien, Penn | H39: =if('QB Formula'!P39 = 0, " ", 'QB Formula'!P39) -> 3.6857143 | J39: ='QB Formula'!C39 -> Y | K39: ='RB Formula'!A39&", "&'RB Formula'!B39 -> Landan Harris, Sam Houston | R39: =if('RB Formula'!R39 = 0, " ", 'RB Formula'!S39) -> 4.3166667 | S39: ='RB Formula'!B39 -> Sam Houston | T39: ='RB Formula'!C39 -> N | U39: ='WR Formula'!A39&", "&'WR Formula'!B39 -> Darren Morris, Southern | AB39: =if('WR Formula'!N39 = 0, " ", 'WR Formula'!P39) -> 4.6 | AC39: ='WR Formula'!B39 -> Southern | AD39: ='WR Formula'!C39 -> Y | AE39: ='TE Formula'!A39&", "&'TE Formula'!B39 -> Nader Chirchi, UConn | AL39: =if('TE Formula'!P39 = 0, " ", 'TE Formula'!R39) | AM39: ='TE Formula'!B39 -> UConn | AN39: ='TE Formula'!C39 -> N | AO39: ='OT Formula'!A39&", "&'OT Formula'!B39 -> Mark Robinson, UTEP | AV39: =if('OT Formula'!N39 = 0, " ", 'OT Formula'!O39) -> 4.0633333 | AW39: ='OT Formula'!B39 -> UTEP | AX39: ='OT Formula'!C39 -> Y | AY39: ='IOL Formula'!A39&", "&'IOL Formula'!B39 -> Aitor Urionabarrenechea, Colorado State | BF39: =if('IOL Formula'!N39 = 0, " ", 'IOL Formula'!O39) -> 3.2366667 | BG39: ='IOL Formula'!B39 -> Colorado State | BH39: ='IOL Formula'!C39 -> Y
A40: ='QB Formula'!A40&", "&'QB Formula'!B40 -> Jared Lockhart, Jackson State | H40: =if('QB Formula'!P40 = 0, " ", 'QB Formula'!P40) -> 3.68309 | J40: ='QB Formula'!C40 -> N | K40: ='RB Formula'!A40&", "&'RB Formula'!B40 -> Will Henderson III, UTSA | R40: =if('RB Formula'!R40 = 0, " ", 'RB Formula'!S40) -> 4.3166667 | S40: ='RB Formula'!B40 -> UTSA | T40: ='RB Formula'!C40 -> N | U40: ='WR Formula'!A40&", "&'WR Formula'!B40 -> Kareem Burke, Arkansas Pine Bluff | AB40: =if('WR Formula'!N40 = 0, " ", 'WR Formula'!P40) -> 4.5714286 | AC40: ='WR Formula'!B40 -> Arkansas Pine Bluff | AD40: ='WR Formula'!C40 -> Y | AE40: ='TE Formula'!A40&", "&'TE Formula'!B40 -> Bryan Henry, Abilene Christian | AL40: =if('TE Formula'!P40 = 0, " ", 'TE Formula'!R40) | AM40: ='TE Formula'!B40 -> Abilene Christian | AN40: ='TE Formula'!C40 -> N | AO40: ='OT Formula'!A40&", "&'OT Formula'!B40 -> Brandon Sneh, UAB | AV40: =if('OT Formula'!N40 = 0, " ", 'OT Formula'!O40) -> 4.02 | AW40: ='OT Formula'!B40 -> UAB | AX40: ='OT Formula'!C40 -> Y | AY40: ='IOL Formula'!A40&", "&'IOL Formula'!B40 -> Patrick Valent, Rice | BF40: =if('IOL Formula'!N40 = 0, " ", 'IOL Formula'!O40) -> 3.1833333 | BG40: ='IOL Formula'!B40 -> Rice | BH40: ='IOL Formula'!C40 -> N
A41: ='QB Formula'!A41&", "&'QB Formula'!B41 -> Carson Camp, Southeastern Louisiana | H41: =if('QB Formula'!P41 = 0, " ", 'QB Formula'!P41) -> 3.6314286 | J41: ='QB Formula'!C41 -> Y | K41: ='RB Formula'!A41&", "&'RB Formula'!B41 -> Eli Gillman, Montana | R41: =if('RB Formula'!R41 = 0, " ", 'RB Formula'!S41) -> 4.3166667 | S41: ='RB Formula'!B41 -> Montana | T41: ='RB Formula'!C41 -> N | U41: ='WR Formula'!A41&", "&'WR Formula'!B41 -> Nico Brown, Yale | AB41: =if('WR Formula'!N41 = 0, " ", 'WR Formula'!P41) -> 4.5571429 | AC41: ='WR Formula'!B41 -> Yale | AD41: ='WR Formula'!C41 -> Y | AE41: ='TE Formula'!A41&", "&'TE Formula'!B41 -> Peyton Strickland, New Hampshire | AL41: =if('TE Formula'!P41 = 0, " ", 'TE Formula'!R41) | AM41: ='TE Formula'!B41 -> New Hampshire | AN41: ='TE Formula'!C41 -> Y | AO41: ='OT Formula'!A41&", "&'OT Formula'!B41 -> Derek Osman, Harvard | AV41: =if('OT Formula'!N41 = 0, " ", 'OT Formula'!O41) -> 4.02 | AW41: ='OT Formula'!B41 -> Harvard | AX41: ='OT Formula'!C41 -> Y | AY41: ='IOL Formula'!A41&", "&'IOL Formula'!B41 -> Adam Lepkowski, UAB | BF41: =if('IOL Formula'!N41 = 0, " ", 'IOL Formula'!O41) -> 2.9266667 | BG41: ='IOL Formula'!B41 -> UAB | BH41: ='IOL Formula'!C41 -> N
A42: ='QB Formula'!A42&", "&'QB Formula'!B42 -> Brayden Fowler-Nicolosi, Colorado State | H42: =if('QB Formula'!P42 = 0, " ", 'QB Formula'!P42) -> 3.5788043 | J42: ='QB Formula'!C42 -> Y | K42: ='RB Formula'!A42&", "&'RB Formula'!B42 -> Sawyer Seidl, North Dakota | R42: =if('RB Formula'!R42 = 0, " ", 'RB Formula'!S42) -> 4.3166667 | S42: ='RB Formula'!B42 -> North Dakota | T42: ='RB Formula'!C42 -> Y | U42: ='WR Formula'!A42&", "&'WR Formula'!B42 -> Chris Marshall, Boise State | AB42: =if('WR Formula'!N42 = 0, " ", 'WR Formula'!P42) -> 4.5571429 | AC42: ='WR Formula'!B42 -> Boise State | AD42: ='WR Formula'!C42 -> N | AE42: ='TE Formula'!A42&", "&'TE Formula'!B42 -> , | AL42: =if('TE Formula'!P42 = 0, " ", 'TE Formula'!R42) | AM42: ='TE Formula'!B42 | AN42: ='TE Formula'!C42 | AO42: ='OT Formula'!A42&", "&'OT Formula'!B42 -> Maasai King, Akron | AV42: =if('OT Formula'!N42 = 0, " ", 'OT Formula'!O42) -> 4.02 | AW42: ='OT Formula'!B42 -> Akron | AX42: ='OT Formula'!C42 -> Y | AY42: ='IOL Formula'!A42&", "&'IOL Formula'!B42 -> Vincent Fiacable, FAU | BF42: =if('IOL Formula'!N42 = 0, " ", 'IOL Formula'!O42) | BG42: ='IOL Formula'!B42 -> FAU | BH42: ='IOL Formula'!C42 -> N
A43: ='QB Formula'!A43&", "&'QB Formula'!B43 -> Johnny Weber, SEMO | H43: =if('QB Formula'!P43 = 0, " ", 'QB Formula'!P43) -> 3.4285714 | J43: ='QB Formula'!C43 -> N | K43: ='RB Formula'!A43&", "&'RB Formula'!B43 -> Scottre Humphrey, New Mexico | R43: =if('RB Formula'!R43 = 0, " ", 'RB Formula'!S43) -> 4.0833333 | S43: ='RB Formula'!B43 -> New Mexico | T43: ='RB Formula'!C43 -> N | U43: ='WR Formula'!A43&", "&'WR Formula'!B43 -> Sam Milligan, Bucknell | AB43: =if('WR Formula'!N43 = 0, " ", 'WR Formula'!P43) -> 4.5285714 | AC43: ='WR Formula'!B43 -> Bucknell | AD43: ='WR Formula'!C43 -> N | AE43: ='TE Formula'!A43&", "&'TE Formula'!B43 -> , | AL43: =if('TE Formula'!P43 = 0, " ", 'TE Formula'!R43) | AM43: ='TE Formula'!B43 | AN43: ='TE Formula'!C43 | AO43: ='OT Formula'!A43&", "&'OT Formula'!B43 -> Reggie Jackson, Jacksonville State | AV43: =if('OT Formula'!N43 = 0, " ", 'OT Formula'!O43) -> 4.0166667 | AW43: ='OT Formula'!B43 -> Jacksonville State | AX43: ='OT Formula'!C43 -> Y | AY43: ='IOL Formula'!A43&", "&'IOL Formula'!B43 -> Zach Greenberg, James Madison | BF43: =if('IOL Formula'!N43 = 0, " ", 'IOL Formula'!O43) | BG43: ='IOL Formula'!B43 -> James Madison | BH43: ='IOL Formula'!C43 -> N
... A53: ='QB Formula'!A53&", "&'QB Formula'!B53 -> , | H53: =if('QB Formula'!P53 = 0, " ", 'QB Formula'!P53) | J53: ='QB Formula'!C53 | K53: ='RB Formula'!A53&", "&'RB Formula'!B53 -> Marlon Gunn, East Carolina | R53: =if('RB Formula'!R53 = 0, " ", 'RB Formula'!S53) -> 3.9958333 | S53: ='RB Formula'!B53 -> East Carolina | T53: ='RB Formula'!C53 -> N | U53: ='WR Formula'!A53&", "&'WR Formula'!B53 -> Beau Sparks, Texas State | AB53: =if('WR Formula'!N53 = 0, " ", 'WR Formula'!P53) -> 4.4 | AC53: ='WR Formula'!B53 -> Texas State | AD53: ='WR Formula'!C53 -> N | AE53: ='TE Formula'!A53&", "&'TE Formula'!B53 -> , | AL53: =if('TE Formula'!P53 = 0, " ", 'TE Formula'!R53) | AM53: ='TE Formula'!B53 | AN53: ='TE Formula'!C53 | AO53: ='OT Formula'!A53&", "&'OT Formula'!B53 -> Greg Nunnery, Southern Miss | AV53: =if('OT Formula'!N53 = 0, " ", 'OT Formula'!O53) | AW53: ='OT Formula'!B53 -> Southern Miss | AX53: ='OT Formula'!C53 -> N | AY53: ='IOL Formula'!A53&", "&'IOL Formula'!B53 -> , | BF53: =if('IOL Formula'!N53 = 0, " ", 'IOL Formula'!O53) | BG53: ='IOL Formula'!B53 | BH53: ='IOL Formula'!C53
A54: ='QB Formula'!A54&", "&'QB Formula'!B54 -> , | H54: =if('QB Formula'!P54 = 0, " ", 'QB Formula'!P54) | J54: ='QB Formula'!C54 | K54: ='RB Formula'!A54&", "&'RB Formula'!B54 -> Kaden Shields-Dutton, Florida Atlantic | R54: =if('RB Formula'!R54 = 0, " ", 'RB Formula'!S54) -> 3.9958333 | S54: ='RB Formula'!B54 -> Florida Atlantic | T54: ='RB Formula'!C54 -> N | U54: ='WR Formula'!A54&", "&'WR Formula'!B54 -> Tommy McIntosh, Central Michigan | AB54: =if('WR Formula'!N54 = 0, " ", 'WR Formula'!P54) -> 4.4 | AC54: ='WR Formula'!B54 -> Central Michigan | AD54: ='WR Formula'!C54 -> N | AE54: ='TE Formula'!A54&", "&'TE Formula'!B54 -> , | AL54: =if('TE Formula'!P54 = 0, " ", 'TE Formula'!R54) | AN54: ='TE Formula'!C54 | AO54: ='OT Formula'!A54&", "&'OT Formula'!B54 -> Jack Foster, Nevada | AV54: =if('OT Formula'!N54 = 0, " ", 'OT Formula'!O54) | AW54: ='OT Formula'!B54 -> Nevada | AX54: ='OT Formula'!C54 -> N | AY54: ='IOL Formula'!A54&", "&'IOL Formula'!B54 -> , | BF54: =if('IOL Formula'!N54 = 0, " ", 'IOL Formula'!O54) | BG54: ='IOL Formula'!B54 | BH54: ='IOL Formula'!C54
A55: ='QB Formula'!A55&", "&'QB Formula'!B55 -> , | H55: =if('QB Formula'!P55 = 0, " ", 'QB Formula'!P55) | J55: ='QB Formula'!C55 | K55: ='RB Formula'!A55&", "&'RB Formula'!B55 -> Bryan Jackson, USC | R55: =if('RB Formula'!R55 = 0, " ", 'RB Formula'!S55) -> 3.9958333 | S55: ='RB Formula'!B55 -> USC | T55: ='RB Formula'!C55 -> Y | U55: ='WR Formula'!A55&", "&'WR Formula'!B55 -> Larry Simmons, Utah | AB55: =if('WR Formula'!N55 = 0, " ", 'WR Formula'!P55) -> 4.4 | AC55: ='WR Formula'!B55 -> Utah | AD55: ='WR Formula'!C55 -> N | AE55: ='TE Formula'!A55&", "&'TE Formula'!B55 -> , | AL55: =if('TE Formula'!P55 = 0, " ", 'TE Formula'!R55) | AN55: ='TE Formula'!C55 | AO55: ='OT Formula'!A55&", "&'OT Formula'!B55 -> Sully Burns, Texas State | AV55: =if('OT Formula'!N55 = 0, " ", 'OT Formula'!O55) | AW55: ='OT Formula'!B55 -> Texas State | AX55: ='OT Formula'!C55 -> N | AY55: ='IOL Formula'!A55&", "&'IOL Formula'!B55 -> , | BF55: =if('IOL Formula'!N55 = 0, " ", 'IOL Formula'!O55) | BG55: ='IOL Formula'!B55 | BH55: ='IOL Formula'!C55
A56: ='QB Formula'!A56&", "&'QB Formula'!B56 -> , | H56: =if('QB Formula'!P56 = 0, " ", 'QB Formula'!P56) | J56: ='QB Formula'!C56 | K56: ='RB Formula'!A56&", "&'RB Formula'!B56 -> Jordan Gant, Akron | R56: =if('RB Formula'!R56 = 0, " ", 'RB Formula'!S56) -> 3.7916667 | S56: ='RB Formula'!B56 -> Akron | T56: ='RB Formula'!C56 -> N | U56: ='WR Formula'!A56&", "&'WR Formula'!B56 -> Danny Scudero, San Jose State | AB56: =if('WR Formula'!N56 = 0, " ", 'WR Formula'!P56) -> 4.3571429 | AC56: ='WR Formula'!B56 -> San Jose State | AD56: ='WR Formula'!C56 -> Y | AE56: ='TE Formula'!A56&", "&'TE Formula'!B56 -> , | AL56: =if('TE Formula'!P56 = 0, " ", 'TE Formula'!R56) | AN56: ='TE Formula'!C56 | AO56: ='OT Formula'!A56&", "&'OT Formula'!B56 -> Nikola Milovac, Kennesaw State | AV56: =if('OT Formula'!N56 = 0, " ", 'OT Formula'!O56) | AW56: ='OT Formula'!B56 -> Kennesaw State | AX56: ='OT Formula'!C56 -> N | AY56: ='IOL Formula'!A56&", "&'IOL Formula'!B56 -> , | BF56: =if('IOL Formula'!N56 = 0, " ", 'IOL Formula'!O56) | BG56: ='IOL Formula'!B56 | BH56: ='IOL Formula'!C56
A57: ='QB Formula'!A57&", "&'QB Formula'!B57 -> , | H57: =if('QB Formula'!P57 = 0, " ", 'QB Formula'!P57) | J57: ='QB Formula'!C57 | K57: ='RB Formula'!A57&", "&'RB Formula'!B57 -> Anthony Carrie, FIU | R57: =if('RB Formula'!R57 = 0, " ", 'RB Formula'!S57) -> 3.7333333 | S57: ='RB Formula'!B57 -> FIU | T57: ='RB Formula'!C57 -> N | U57: ='WR Formula'!A57&", "&'WR Formula'!B57 -> Jeremiah Koger, USF | AB57: =if('WR Formula'!N57 = 0, " ", 'WR Formula'!P57) -> 4.3285714 | AC57: ='WR Formula'!B57 -> USF | AD57: ='WR Formula'!C57 -> N | AE57: ='TE Formula'!A57&", "&'TE Formula'!B57 -> , | AL57: =if('TE Formula'!P57 = 0, " ", 'TE Formula'!R57) | AN57: ='TE Formula'!C57 | AO57: ='OT Formula'!A57&", "&'OT Formula'!B57 -> Tyler Lawrence, New Mexico | AV57: =if('OT Formula'!N57 = 0, " ", 'OT Formula'!O57) | AW57: ='OT Formula'!B57 -> New Mexico | AX57: ='OT Formula'!C57 -> N | AY57: ='IOL Formula'!A57&", "&'IOL Formula'!B57 -> , | BF57: =if('IOL Formula'!N57 = 0, " ", 'IOL Formula'!O57) | BG57: ='IOL Formula'!B57 | BH57: ='IOL Formula'!C57
A58: ='QB Formula'!A58&", "&'QB Formula'!B58 -> , | H58: =if('QB Formula'!P58 = 0, " ", 'QB Formula'!P58) | J58: ='QB Formula'!C58 | K58: ='RB Formula'!A58&", "&'RB Formula'!B58 -> Kente Edwards, Lafayette | R58: =if('RB Formula'!R58 = 0, " ", 'RB Formula'!S58) -> 3.7333333 | S58: ='RB Formula'!B58 -> Lafayette | T58: ='RB Formula'!C58 -> Y | U58: ='WR Formula'!A58&", "&'WR Formula'!B58 -> Malik Knight, Western Carolina | AB58: =if('WR Formula'!N58 = 0, " ", 'WR Formula'!P58) -> 4.3285714 | AC58: ='WR Formula'!B58 -> Western Carolina | AD58: ='WR Formula'!C58 -> Y | AE58: ='TE Formula'!A58&", "&'TE Formula'!B58 -> , | AL58: =if('TE Formula'!P58 = 0, " ", 'TE Formula'!R58) | AN58: ='TE Formula'!C58 | AO58: ='OT Formula'!A58&", "&'OT Formula'!B58 -> Joseph Simmons, James Madison | AV58: =if('OT Formula'!N58 = 0, " ", 'OT Formula'!O58) | AW58: ='OT Formula'!B58 -> James Madison | AX58: ='OT Formula'!C58 -> N | AY58: ='IOL Formula'!A58&", "&'IOL Formula'!B58 -> , | BF58: =if('IOL Formula'!N58 = 0, " ", 'IOL Formula'!O58) | BG58: ='IOL Formula'!B58 | BH58: ='IOL Formula'!C58
A59: ='QB Formula'!A59&", "&'QB Formula'!B59 -> , | H59: =if('QB Formula'!P59 = 0, " ", 'QB Formula'!P59) | J59: ='QB Formula'!C59 | K59: ='RB Formula'!A59&", "&'RB Formula'!B59 -> Ja'Vin Simpkins, Coastal Carolina | R59: =if('RB Formula'!R59 = 0, " ", 'RB Formula'!S59) -> 3.7333333 | S59: ='RB Formula'!B59 -> Coastal Carolina | T59: ='RB Formula'!C59 -> N | U59: ='WR Formula'!A59&", "&'WR Formula'!B59 -> Xayvion Noland, UTRGV | AB59: =if('WR Formula'!N59 = 0, " ", 'WR Formula'!P59) -> 4.3142857 | AC59: ='WR Formula'!B59 -> UTRGV | AD59: ='WR Formula'!C59 -> Y | AE59: ='TE Formula'!A59&", "&'TE Formula'!B59 -> , | AL59: =if('TE Formula'!P59 = 0, " ", 'TE Formula'!R59) | AN59: ='TE Formula'!C59 | AO59: ='OT Formula'!A59&", "&'OT Formula'!B59 -> Austin Boyd, UNLV | AV59: =if('OT Formula'!N59 = 0, " ", 'OT Formula'!O59) | AW59: ='OT Formula'!B59 -> UNLV | AX59: ='OT Formula'!C59 -> N | AY59: ='IOL Formula'!A59&", "&'IOL Formula'!B59 -> , | BF59: =if('IOL Formula'!N59 = 0, " ", 'IOL Formula'!O59) | BG59: ='IOL Formula'!B59 | BH59: ='IOL Formula'!C59
A60: ='QB Formula'!A60&", "&'QB Formula'!B60 -> , | H60: =if('QB Formula'!P60 = 0, " ", 'QB Formula'!P60) | J60: ='QB Formula'!C60 | K60: ='RB Formula'!A60&", "&'RB Formula'!B60 -> Jordan Fisher, UC Davis | R60: =if('RB Formula'!R60 = 0, " ", 'RB Formula'!S60) -> 3.7333333 | S60: ='RB Formula'!B60 -> UC Davis | T60: ='RB Formula'!C60 -> N | U60: ='WR Formula'!A60&", "&'WR Formula'!B60 -> Brock Spalding, ECU | AB60: =if('WR Formula'!N60 = 0, " ", 'WR Formula'!P60) -> 4.2571429 | AC60: ='WR Formula'!B60 -> ECU | AD60: ='WR Formula'!C60 -> N | AE60: ='TE Formula'!A60&", "&'TE Formula'!B60 -> , | AL60: =if('TE Formula'!P60 = 0, " ", 'TE Formula'!R60) | AN60: ='TE Formula'!C60 | AO60: ='OT Formula'!A60&", "&'OT Formula'!B60 -> Noah Rosahac, Delaware | AV60: =if('OT Formula'!N60 = 0, " ", 'OT Formula'!O60) | AW60: ='OT Formula'!B60 -> Delaware | AX60: ='OT Formula'!C60 -> N | AY60: ='IOL Formula'!A60&", "&'IOL Formula'!B60 -> , | BF60: =if('IOL Formula'!N60 = 0, " ", 'IOL Formula'!O60) | BG60: ='IOL Formula'!B60 | BH60: ='IOL Formula'!C60
A61: ='QB Formula'!A61&", "&'QB Formula'!B61 -> , | H61: =if('QB Formula'!P61 = 0, " ", 'QB Formula'!P61) | J61: ='QB Formula'!C61 | K61: ='RB Formula'!A61&", "&'RB Formula'!B61 -> Rovaughn Banks Jr, Abilene Christian | R61: =if('RB Formula'!R61 = 0, " ", 'RB Formula'!S61) -> 3.7333333 | S61: ='RB Formula'!B61 -> Abilene Christian | T61: ='RB Formula'!C61 -> N | U61: ='WR Formula'!A61&", "&'WR Formula'!B61 -> Jordan Napier, San Diego State | AB61: =if('WR Formula'!N61 = 0, " ", 'WR Formula'!P61) -> 4.2571429 | AC61: ='WR Formula'!B61 -> San Diego State | AD61: ='WR Formula'!C61 -> N | AE61: ='TE Formula'!A61&", "&'TE Formula'!B61 -> , | AL61: =if('TE Formula'!P61 = 0, " ", 'TE Formula'!R61) | AN61: ='TE Formula'!C61 | AO61: ='OT Formula'!A61&", "&'OT Formula'!B61 -> Zach Cochnauer, Nevada | AV61: =if('OT Formula'!N61 = 0, " ", 'OT Formula'!O61) | AW61: ='OT Formula'!B61 -> Nevada | AX61: ='OT Formula'!C61 -> N | AY61: ='IOL Formula'!A61&", "&'IOL Formula'!B61 -> , | BF61: =if('IOL Formula'!N61 = 0, " ", 'IOL Formula'!O61) | BG61: ='IOL Formula'!B61 | BH61: ='IOL Formula'!C61
A62: ='QB Formula'!A62&", "&'QB Formula'!B62 -> , | H62: =if('QB Formula'!P62 = 0, " ", 'QB Formula'!P62) | J62: ='QB Formula'!C62 | K62: ='RB Formula'!A62&", "&'RB Formula'!B62 -> TJ Thomas Jr., Elon | R62: =if('RB Formula'!R62 = 0, " ", 'RB Formula'!S62) -> 3.5 | S62: ='RB Formula'!B62 -> Elon | T62: ='RB Formula'!C62 -> N | U62: ='WR Formula'!A62&", "&'WR Formula'!B62 -> Kam Perry, Miami OH | AB62: =if('WR Formula'!N62 = 0, " ", 'WR Formula'!P62) -> 4.2428571 | AC62: ='WR Formula'!B62 -> Miami OH | AD62: ='WR Formula'!C62 -> Y | AE62: ='TE Formula'!A62&", "&'TE Formula'!B62 -> , | AL62: =if('TE Formula'!P62 = 0, " ", 'TE Formula'!R62) | AN62: ='TE Formula'!C62 | AO62: ='OT Formula'!A62&", "&'OT Formula'!B62 -> , | AV62: =if('OT Formula'!N62 = 0, " ", 'OT Formula'!O62) | AW62: ='OT Formula'!B62 | AX62: ='OT Formula'!C62 | AY62: ='IOL Formula'!A62&", "&'IOL Formula'!B62 -> , | BF62: =if('IOL Formula'!N62 = 0, " ", 'IOL Formula'!O62) | BG62: ='IOL Formula'!B62 | BH62: ='IOL Formula'!C62
A63: ='QB Formula'!A63&", "&'QB Formula'!B63 -> , | H63: =if('QB Formula'!P63 = 0, " ", 'QB Formula'!P63) | J63: ='QB Formula'!C63 | K63: ='RB Formula'!A63&", "&'RB Formula'!B63 -> Trequan Jones, Old Dominion | R63: =if('RB Formula'!R63 = 0, " ", 'RB Formula'!S63) -> 3.4708333 | S63: ='RB Formula'!B63 -> Old Dominion | T63: ='RB Formula'!C63 -> Y | U63: ='WR Formula'!A63&", "&'WR Formula'!B63 -> Landon Ellis, James Madison | AB63: =if('WR Formula'!N63 = 0, " ", 'WR Formula'!P63) -> 4.2428571 | AC63: ='WR Formula'!B63 -> James Madison | AD63: ='WR Formula'!C63 -> N | AE63: ='TE Formula'!A63&", "&'TE Formula'!B63 -> , | AL63: =if('TE Formula'!P63 = 0, " ", 'TE Formula'!R63) | AN63: ='TE Formula'!C63 | AO63: ='OT Formula'!A63&", "&'OT Formula'!B63 -> , | AV63: =if('OT Formula'!N63 = 0, " ", 'OT Formula'!O63) | AW63: ='OT Formula'!B63 | AX63: ='OT Formula'!C63 | AY63: ='IOL Formula'!A63&", "&'IOL Formula'!B63 -> , | BF63: =if('IOL Formula'!N63 = 0, " ", 'IOL Formula'!O63) | BG63: ='IOL Formula'!B63 | BH63: ='IOL Formula'!C63
A64: ='QB Formula'!A64&", "&'QB Formula'!B64 -> , | H64: =if('QB Formula'!P64 = 0, " ", 'QB Formula'!P64) | J64: ='QB Formula'!C64 | K64: ='RB Formula'!A64&", "&'RB Formula'!B64 -> Lamar Spurling, Buffalo | R64: =if('RB Formula'!R64 = 0, " ", 'RB Formula'!S64) -> 3.4125 | S64: ='RB Formula'!B64 -> Buffalo | T64: ='RB Formula'!C64 -> N | U64: ='WR Formula'!A64&", "&'WR Formula'!B64 -> Chris Dawn Jr, Texas State | AB64: =if('WR Formula'!N64 = 0, " ", 'WR Formula'!P64) -> 4.2428571 | AC64: ='WR Formula'!B64 -> Texas State | AD64: ='WR Formula'!C64 -> N | AE64: ='TE Formula'!A64&", "&'TE Formula'!B64 -> , | AL64: =if('TE Formula'!P64 = 0, " ", 'TE Formula'!R64) | AN64: ='TE Formula'!C64 | AO64: ='OT Formula'!A64&", "&'OT Formula'!B64 -> , | AV64: =if('OT Formula'!N64 = 0, " ", 'OT Formula'!O64) | AW64: ='OT Formula'!B64 | AX64: ='OT Formula'!C64 | AY64: ='IOL Formula'!A64&", "&'IOL Formula'!B64 -> , | BF64: =if('IOL Formula'!N64 = 0, " ", 'IOL Formula'!O64) | BG64: ='IOL Formula'!B64 | BH64: ='IOL Formula'!C64
A65: ='QB Formula'!A65&", "&'QB Formula'!B65 -> , | H65: =if('QB Formula'!P65 = 0, " ", 'QB Formula'!P65) | J65: ='QB Formula'!C65 | K65: ='RB Formula'!A65&", "&'RB Formula'!B65 -> Gerald Modest, Wofford | R65: =if('RB Formula'!R65 = 0, " ", 'RB Formula'!S65) -> 3.4125 | S65: ='RB Formula'!B65 -> Wofford | T65: ='RB Formula'!C65 -> Y | U65: ='WR Formula'!A65&", "&'WR Formula'!B65 -> Moussa Barry, Western Kentucky | AB65: =if('WR Formula'!N65 = 0, " ", 'WR Formula'!P65) -> 4.2428571 | AC65: ='WR Formula'!B65 -> Western Kentucky | AD65: ='WR Formula'!C65 -> N | AE65: ='TE Formula'!A65&", "&'TE Formula'!B65 -> , | AL65: =if('TE Formula'!P65 = 0, " ", 'TE Formula'!R65) | AN65: ='TE Formula'!C65 | AO65: ='OT Formula'!A65&", "&'OT Formula'!B65 -> , | AV65: =if('OT Formula'!N65 = 0, " ", 'OT Formula'!O65) | AW65: ='OT Formula'!B65 | AX65: ='OT Formula'!C65 | AY65: ='IOL Formula'!A65&", "&'IOL Formula'!B65 -> , | BF65: =if('IOL Formula'!N65 = 0, " ", 'IOL Formula'!O65) | BG65: ='IOL Formula'!B65 | BH65: ='IOL Formula'!C65
...

Sheet QB
A1: Name | B1: COLLEGE | C1: TRANSFER PORTAL | D1: TIER | E1: SCHEME FIT | G1: ARCHETYPE | I1: Arm Strength | J1: Gets Past First Read | K1: Success over MOF | L1: Success towards Field Sideline | M1: Pocket Mobility | N1: Elusiveness Behind LOS | O1: Open Field Speed | P1: GRADE | Q1: DIFFERENTIAL | R1: AA Grade | T1: Grade | U1: Grade | V1: Grade | W1: Grade | X1: Grade | Y1: Grade | Z1: Grade | AD1: Grade | AF1: Grade | AH1: Grade | AJ1: Grade | AL1: Grade | AN1: Grade | AP1: Grade
A2: Brandon Tennison | B2: UTSA | C2: N | D2: =ifs(P2 = 0, "",P2<3.25, "G5 Backup QB", P2<3.75, "G5 Spot Starting QB",P2 < 4.25, "G5 Starter QB",P2 < 4.5, "P4 Spot Starting QB", P2 >= 4.5, "P4 Starter QB" ) -> G5 Spot Starting QB | E2: =If(T2>4.2, "Vertical Passing, ","Short/Intermediate, ")&if(U2>4.2, "Full-Field Progression Offense", "Half-Field Progression") -> Short/Intermediate, Half-Field Progression | G2: =IFS(AND(Q2<-1, T2<4), "Chain Mover w/Arm or Leg", AND(T2>5, Z2>5), "Elite Athlete at QB", AND(T2>5, X2<2.5), "Statue In Pocket Passer", AND(T2>5, X2<4), "Pocket Passer", AND(P2<4, Q2>1), "Chain Mover w/Arm", AND(T2>3, Z2>3), "Functional Athlete at QB") -> Functional Athlete at QB | I2: Ball Dips, Any Platform | J2: Telegraphs Reads Post Snap | K2: Timing Is Off | L2: Anticipates Throw, Ball Is In Defender's Reach | M2: Can Move Around But Doesn't Always Anticipate Pressure | N2: Moves But Easily Chased By Defenders | O2: Gets Yard In Open Space | P2: =iferror((sum(T2:W2)*1.1+sum(X2:Z2)*0.9)/7,0) -> 3.7009471 | Q2: =(sum(T2:W2)-sum(X2:Z2)*1.3) -> -4.1967 | T2: =iferror(XLOOKUP(I2, $AC$2:$AC$6,$AD$2:$AD$6), 0) -> 4.2 | U2: =iferror(XLOOKUP(J2, $AE$2:$AE$6,$AF$2:$AF$6), 0) -> 2.8 | V2: =iferror(XLOOKUP(K2, $AG$2:$AG$6,$AH$2:$AH$6), 0) -> 2.3333 | W2: =iferror(XLOOKUP(L2, $AI$2:$AI$6,$AJ$2:$AJ$6), 0) -> 3.5 | X2: =iferror(XLOOKUP(M2, $AK$2:$AK$6,$AL$2:$AL$6), 0) -> 5.6 | Y2: =iferror(XLOOKUP(N2, $AM$2:$AM$6,$AN$2:$AN$6), 0) -> 4 | Z2: =iferror(XLOOKUP(O2, $AO$2:$AO$6,$AP$2:$AP$6), 0) -> 3.5 | AC2: Any Throw, Any Platform | AD2: 7 | AE2: Consistently Works Thru Full-Field Reads | AF2: 7 | AG2: Consistent Seam Beater | AH2: 7 | AI2: No Velocity Dip On Field Side Throws | AJ2: 7 | AK2: Quick Twitch, Anticipates, Escapes Tight Pocket | AL2: 7 | AM2: Makes Defenders Miss/Anticipatory Vision | AN2: 6 | AO2: Final Gear at 3rd Level | AP2: 7
A3: Brayden Fowler-Nicolosi | B3: Colorado State | C3: Y | D3: =ifs(P3 = 0, "",P3<3.25, "G5 Backup QB", P3<3.75, "G5 Spot Starting QB",P3 < 4.25, "G5 Starter QB",P3 < 4.5, "P4 Spot Starting QB", P3 >= 4.5, "P4 Starter QB" ) -> G5 Spot Starting QB | E3: =If(T3>4.2, "Vertical Passing, ","Short/Intermediate, ")&if(U3>4.2, "Full-Field Progression Offense", "Half-Field Progression") -> Vertical Passing, Half-Field Progression | G3: =IFS(AND(Q3<-1, T3<4), "Chain Mover w/Arm or Leg", AND(T3>5, Z3>5), "Elite Athlete at QB", AND(T3>5, X3<2.5), "Statue In Pocket Passer", AND(T3>5, X3<4), "Pocket Passer", AND(P3<4, Q3>1), "Chain Mover w/Arm", AND(T3>3, Z3>3), "Functional Athlete at QB") -> Pocket Passer | I3: Any Throw, Firm Base | J3: Telegraphs Reads Post Snap | K3: Timing Is Off | L3: Frequently Hits Hole Shots | M3: Throws Thru Pressure | N3: Resorts to Throwaway/Expects To Get Hit | O3: Gets Yard In Open Space | P3: =iferror((sum(T3:W3)*1.1+sum(X3:Z3)*0.9)/7,0) -> 3.5788043 | Q3: =(sum(T3:W3)-sum(X3:Z3)*1.3) -> 5.1933 | T3: =iferror(XLOOKUP(I3, $AC$2:$AC$6,$AD$2:$AD$6), 0) -> 5.6 | U3: =iferror(XLOOKUP(J3, $AE$2:$AE$6,$AF$2:$AF$6), 0) -> 2.8 | V3: =iferror(XLOOKUP(K3, $AG$2:$AG$6,$AH$2:$AH$6), 0) -> 2.3333 | W3: =iferror(XLOOKUP(L3, $AI$2:$AI$6,$AJ$2:$AJ$6), 0) -> 5.25 | X3: =iferror(XLOOKUP(M3, $AK$2:$AK$6,$AL$2:$AL$6), 0) -> 2.8 | Y3: =iferror(XLOOKUP(N3, $AM$2:$AM$6,$AN$2:$AN$6), 0) -> 2 | Z3: =iferror(XLOOKUP(O3, $AO$2:$AO$6,$AP$2:$AP$6), 0) -> 3.5 | AC3: Any Throw, Firm Base | AD3: 5.6 | AE3: Will Occasionally Get To 3rd Read | AF3: 5.6 | AG3: Can Hit, Struggles In Tight Windows | AH3: 4.6 | AI3: Frequently Hits Hole Shots | AJ3: 5.25 | AK3: Can Move Around But Doesn't Always Anticipate Pressure | AL3: 5.6 | AM3: Moves But Easily Chased By Defenders | AN3: 4 | AO3: Good Space Eater | AP3: 5.25
A4: Hauss Hejny | B4: Oklahoma State | C4: N | D4: =ifs(P4 = 0, "",P4<3.25, "G5 Backup QB", P4<3.75, "G5 Spot Starting QB",P4 < 4.25, "G5 Starter QB",P4 < 4.5, "P4 Spot Starting QB", P4 >= 4.5, "P4 Starter QB" ) -> P4 Starter QB | E4: =If(T4>4.2, "Vertical Passing, ","Short/Intermediate, ")&if(U4>4.2, "Full-Field Progression Offense", "Half-Field Progression") -> Vertical Passing, Half-Field Progression | G4: =IFS(AND(Q4<-1, T4<4), "Chain Mover w/Arm or Leg", AND(T4>5, Z4>5), "Elite Athlete at QB", AND(T4>5, X4<2.5), "Statue In Pocket Passer", AND(T4>5, X4<4), "Pocket Passer", AND(P4<4, Q4>1), "Chain Mover w/Arm", AND(T4>3, Z4>3), "Functional Athlete at QB") -> Elite Athlete at QB | I4: Any Throw, Firm Base | J4: Correctly Deciphers Half Field Reads | K4: Can Hit, Struggles In Tight Windows | L4: Frequently Hits Hole Shots | M4: Can Move Around But Doesn't Always Anticipate Pressure | N4: Moves But Easily Chased By Defenders | O4: Good Space Eater | P4: =iferror((sum(T4:W4)*1.1+sum(X4:Z4)*0.9)/7,0) -> 4.9971429 | Q4: =(sum(T4:W4)-sum(X4:Z4)*1.3) -> 0.345 | T4: =iferror(XLOOKUP(I4, $AC$2:$AC$6,$AD$2:$AD$6), 0) -> 5.6 | U4: =iferror(XLOOKUP(J4, $AE$2:$AE$6,$AF$2:$AF$6), 0) -> 4.2 | V4: =iferror(XLOOKUP(K4, $AG$2:$AG$6,$AH$2:$AH$6), 0) -> 4.6 | W4: =iferror(XLOOKUP(L4, $AI$2:$AI$6,$AJ$2:$AJ$6), 0) -> 5.25 | X4: =iferror(XLOOKUP(M4, $AK$2:$AK$6,$AL$2:$AL$6), 0) -> 5.6 | Y4: =iferror(XLOOKUP(N4, $AM$2:$AM$6,$AN$2:$AN$6), 0) -> 4 | Z4: =iferror(XLOOKUP(O4, $AO$2:$AO$6,$AP$2:$AP$6), 0) -> 5.25 | AC4: Ball Dips, Any Platform | AD4: 4.2 | AE4: Correctly Deciphers Half Field Reads | AF4: 4.2 | AG4: Timing Is Off | AH4: 2.3333 | AI4: Anticipates Throw, Ball Is In Defender's Reach | AJ4: 3.5 | AK4: Likely to Bail From Clean Pocket | AL4: 4.2 | AM4: Resorts to Throwaway/Expects To Get Hit | AN4: 2 | AO4: Gets Yard In Open Space | AP4: 3.5
A5: Zane Flores | B5: Oklahoma State | C5: Y | D5: =ifs(P5 = 0, "",P5<3.25, "G5 Backup QB", P5<3.75, "G5 Spot Starting QB",P5 < 4.25, "G5 Starter QB",P5 < 4.5, "P4 Spot Starting QB", P5 >= 4.5, "P4 Starter QB" ) -> P4 Spot Starting QB | E5: =If(T5>4.2, "Vertical Passing, ","Short/Intermediate, ")&if(U5>4.2, "Full-Field Progression Offense", "Half-Field Progression") -> Short/Intermediate, Half-Field Progression | G5: =IFS(AND(Q5<-1, T5<4), "Chain Mover w/Arm or Leg", AND(T5>5, Z5>5), "Elite Athlete at QB", AND(T5>5, X5<2.5), "Statue In Pocket Passer", AND(T5>5, X5<4), "Pocket Passer", AND(P5<4, Q5>1), "Chain Mover w/Arm", AND(T5>3, Z5>3), "Functional Athlete at QB") -> Functional Athlete at QB | I5: Ball Dips, Any Platform | J5: Correctly Deciphers Half Field Reads | K5: Can Hit, Struggles In Tight Windows | L5: Frequently Hits Hole Shots | M5: Likely to Bail From Clean Pocket | N5: Moves But Easily Chased By Defenders | O5: Gets Yard In Open Space | P5: =iferror((sum(T5:W5)*1.1+sum(X5:Z5)*0.9)/7,0) -> 4.3721429 | Q5: =(sum(T5:W5)-sum(X5:Z5)*1.3) -> 3.04 | T5: =iferror(XLOOKUP(I5, $AC$2:$AC$6,$AD$2:$AD$6), 0) -> 4.2 | U5: =iferror(XLOOKUP(J5, $AE$2:$AE$6,$AF$2:$AF$6), 0) -> 4.2 | V5: =iferror(XLOOKUP(K5, $AG$2:$AG$6,$AH$2:$AH$6), 0) -> 4.6 | W5: =iferror(XLOOKUP(L5, $AI$2:$AI$6,$AJ$2:$AJ$6), 0) -> 5.25 | X5: =iferror(XLOOKUP(M5, $AK$2:$AK$6,$AL$2:$AL$6), 0) -> 4.2 | Y5: =iferror(XLOOKUP(N5, $AM$2:$AM$6,$AN$2:$AN$6), 0) -> 4 | Z5: =iferror(XLOOKUP(O5, $AO$2:$AO$6,$AP$2:$AP$6), 0) -> 3.5 | AC5: Ball Dips, Firm Base | AD5: 2.8 | AE5: Telegraphs Reads Post Snap | AF5: 2.8 | AI5: Ball Dips To Open Receiver | AJ5: 1.75 | AK5: Throws Thru Pressure | AL5: 2.8 | AO5: Looks Reluctant To Run | AP5: 1.75
A6: Davin Wydner | B6: West Georgia | C6: Y | D6: =ifs(P6 = 0, "",P6<3.25, "G5 Backup QB", P6<3.75, "G5 Spot Starting QB",P6 < 4.25, "G5 Starter QB",P6 < 4.5, "P4 Spot Starting QB", P6 >= 4.5, "P4 Starter QB" ) -> G5 Starter QB | E6: =If(T6>4.2, "Vertical Passing, ","Short/Intermediate, ")&if(U6>4.2, "Full-Field Progression Offense", "Half-Field Progression") -> Short/Intermediate, Half-Field Progression | G6: =IFS(AND(Q6<-1, T6<4), "Chain Mover w/Arm or Leg", AND(T6>5, Z6>5), "Elite Athlete at QB", AND(T6>5, X6<2.5), "Statue In Pocket Passer", AND(T6>5, X6<4), "Pocket Passer", AND(P6<4, Q6>1), "Chain Mover w/Arm", AND(T6>3, Z6>3), "Functional Athlete at QB") -> Functional Athlete at QB | I6: Ball Dips, Any Platform | J6: Telegraphs Reads Post Snap | K6: Timing Is Off | L6: Frequently Hits Hole Shots | M6: Likely to Bail From Clean Pocket | N6: Moves But Easily Chased By Defenders | O6: Gets Yard In Open Space | P6: =iferror((sum(T6:W6)*1.1+sum(X6:Z6)*0.9)/7,0) -> 3.7959471 | Q6: =(sum(T6:W6)-sum(X6:Z6)*1.3) -> -0.6267 | T6: =iferror(XLOOKUP(I6, $AC$2:$AC$6,$AD$2:$AD$6), 0) -> 4.2 | U6: =iferror(XLOOKUP(J6, $AE$2:$AE$6,$AF$2:$AF$6), 0) -> 2.8 | V6: =iferror(XLOOKUP(K6, $AG$2:$AG$6,$AH$2:$AH$6), 0) -> 2.3333 | W6: =iferror(XLOOKUP(L6, $AI$2:$AI$6,$AJ$2:$AJ$6), 0) -> 5.25 | X6: =iferror(XLOOKUP(M6, $AK$2:$AK$6,$AL$2:$AL$6), 0) -> 4.2 | Y6: =iferror(XLOOKUP(N6, $AM$2:$AM$6,$AN$2:$AN$6), 0) -> 4 | Z6: =iferror(XLOOKUP(O6, $AO$2:$AO$6,$AP$2:$AP$6), 0) -> 3.5 | AC6: Arm Strength Increases On The Run | AD6: 1 | AE6: Won't Process Reads | AF6: 1 | AK6: Statue In Pocket | AL6: 1
A7: Devon Dampier | B7: Utah | C7: N | D7: =ifs(P7 = 0, "",P7<3.25, "G5 Backup QB", P7<3.75, "G5 Spot Starting QB",P7 < 4.25, "G5 Starter QB",P7 < 4.5, "P4 Spot Starting QB", P7 >= 4.5, "P4 Starter QB" ) -> P4 Starter QB | E7: =If(T7>4.2, "Vertical Passing, ","Short/Intermediate, ")&if(U7>4.2, "Full-Field Progression Offense", "Half-Field Progression") -> Short/Intermediate, Full-Field Progression Offense | G7: =IFS(AND(Q7<-1, T7<4), "Chain Mover w/Arm or Leg", AND(T7>5, Z7>5), "Elite Athlete at QB", AND(T7>5, X7<2.5), "Statue In Pocket Passer", AND(T7>5, X7<4), "Pocket Passer", AND(P7<4, Q7>1), "Chain Mover w/Arm", AND(T7>3, Z7>3), "Functional Athlete at QB") -> Functional Athlete at QB | I7: Ball Dips, Any Platform | J7: Will Occasionally Get To 3rd Read | K7: Can Hit, Struggles In Tight Windows | L7: Anticipates Throw, Ball Is In Defender's Reach | M7: Likely to Bail From Clean Pocket | N7: Makes Defenders Miss/Anticipatory Vision | O7: Gets Yard In Open Space | P7: =iferror((sum(T7:W7)*1.1+sum(X7:Z7)*0.9)/7,0) -> 4.5742857 | Q7: =(sum(T7:W7)-sum(X7:Z7)*1.3) -> 0.09 | T7: =iferror(XLOOKUP(I7, $AC$2:$AC$6,$AD$2:$AD$6), 0) -> 4.2 | U7: =iferror(XLOOKUP(J7, $AE$2:$AE$6,$AF$2:$AF$6), 0) -> 5.6 | V7: =iferror(XLOOKUP(K7, $AG$2:$AG$6,$AH$2:$AH$6), 0) -> 4.6 | W7: =iferror(XLOOKUP(L7, $AI$2:$AI$6,$AJ$2:$AJ$6), 0) -> 3.5 | X7: =iferror(XLOOKUP(M7, $AK$2:$AK$6,$AL$2:$AL$6), 0) -> 4.2 | Y7: =iferror(XLOOKUP(N7, $AM$2:$AM$6,$AN$2:$AN$6), 0) -> 6 | Z7: =iferror(XLOOKUP(O7, $AO$2:$AO$6,$AP$2:$AP$6), 0) -> 3.5
A8: Wyatt Bower | B8: Ferris State | C8: N | D8: =ifs(P8 = 0, "",P8<3.25, "G5 Backup QB", P8<3.75, "G5 Spot Starting QB",P8 < 4.25, "G5 Starter QB",P8 < 4.5, "P4 Spot Starting QB", P8 >= 4.5, "P4 Starter QB" ) -> P4 Spot Starting QB | E8: =If(T8>4.2, "Vertical Passing, ","Short/Intermediate, ")&if(U8>4.2, "Full-Field Progression Offense", "Half-Field Progression") -> Short/Intermediate, Half-Field Progression | G8: =IFS(AND(Q8<-1, T8<4), "Chain Mover w/Arm or Leg", AND(T8>5, Z8>5), "Elite Athlete at QB", AND(T8>5, X8<2.5), "Statue In Pocket Passer", AND(T8>5, X8<4), "Pocket Passer", AND(P8<4, Q8>1), "Chain Mover w/Arm", AND(T8>3, Z8>3), "Functional Athlete at QB") -> Functional Athlete at QB | I8: Ball Dips, Any Platform | J8: Telegraphs Reads Post Snap | K8: Can Hit, Struggles In Tight Windows | L8: Anticipates Throw, Ball Is In Defender's Reach | M8: Likely to Bail From Clean Pocket | N8: Makes Defenders Miss/Anticipatory Vision | O8: Good Space Eater | P8: =iferror((sum(T8:W8)*1.1+sum(X8:Z8)*0.9)/7,0) -> 4.3592857 | Q8: =(sum(T8:W8)-sum(X8:Z8)*1.3) -> -4.985 | T8: =iferror(XLOOKUP(I8, $AC$2:$AC$6,$AD$2:$AD$6), 0) -> 4.2 | U8: =iferror(XLOOKUP(J8, $AE$2:$AE$6,$AF$2:$AF$6), 0) -> 2.8 | V8: =iferror(XLOOKUP(K8, $AG$2:$AG$6,$AH$2:$AH$6), 0) -> 4.6 | W8: =iferror(XLOOKUP(L8, $AI$2:$AI$6,$AJ$2:$AJ$6), 0) -> 3.5 | X8: =iferror(XLOOKUP(M8, $AK$2:$AK$6,$AL$2:$AL$6), 0) -> 4.2 | Y8: =iferror(XLOOKUP(N8, $AM$2:$AM$6,$AN$2:$AN$6), 0) -> 6 | Z8: =iferror(XLOOKUP(O8, $AO$2:$AO$6,$AP$2:$AP$6), 0) -> 5.25
A9: Byrd Ficklin | B9: Utah | C9: N | D9: =ifs(P9 = 0, "",P9<3.25, "G5 Backup QB", P9<3.75, "G5 Spot Starting QB",P9 < 4.25, "G5 Starter QB",P9 < 4.5, "P4 Spot Starting QB", P9 >= 4.5, "P4 Starter QB" ) -> P4 Starter QB | E9: =If(T9>4.2, "Vertical Passing, ","Short/Intermediate, ")&if(U9>4.2, "Full-Field Progression Offense", "Half-Field Progression") -> Short/Intermediate, Half-Field Progression | G9: =IFS(AND(Q9<-1, T9<4), "Chain Mover w/Arm or Leg", AND(T9>5, Z9>5), "Elite Athlete at QB", AND(T9>5, X9<2.5), "Statue In Pocket Passer", AND(T9>5, X9<4), "Pocket Passer", AND(P9<4, Q9>1), "Chain Mover w/Arm", AND(T9>3, Z9>3), "Functional Athlete at QB") -> Functional Athlete at QB | I9: Ball Dips, Any Platform | J9: Telegraphs Reads Post Snap | K9: Can Hit, Struggles In Tight Windows | L9: Anticipates Throw, Ball Is In Defender's Reach | M9: Can Move Around But Doesn't Always Anticipate Pressure | N9: Makes Defenders Miss/Anticipatory Vision | O9: Good Space Eater | P9: =iferror((sum(T9:W9)*1.1+sum(X9:Z9)*0.9)/7,0) -> 4.5392857 | Q9: =(sum(T9:W9)-sum(X9:Z9)*1.3) -> -6.805 | T9: =iferror(XLOOKUP(I9, $AC$2:$AC$6,$AD$2:$AD$6), 0) -> 4.2 | U9: =iferror(XLOOKUP(J9, $AE$2:$AE$6,$AF$2:$AF$6), 0) -> 2.8 | V9: =iferror(XLOOKUP(K9, $AG$2:$AG$6,$AH$2:$AH$6), 0) -> 4.6 | W9: =iferror(XLOOKUP(L9, $AI$2:$AI$6,$AJ$2:$AJ$6), 0) -> 3.5 | X9: =iferror(XLOOKUP(M9, $AK$2:$AK$6,$AL$2:$AL$6), 0) -> 5.6 | Y9: =iferror(XLOOKUP(N9, $AM$2:$AM$6,$AN$2:$AN$6), 0) -> 6 | Z9: =iferror(XLOOKUP(O9, $AO$2:$AO$6,$AP$2:$AP$6), 0) -> 5.25
